Workbook

Sheet CÁLCULO ESTABILIDADE
D2: NAVIO GODINHO 2022
D3: INSTRUÇÕES: Dentro das células abaixo insira os valores dos respectivos pesos embarcados em cada tanque e/ou porão. E, nas células abaixo da imagem do navio devem ser inseridos os respectivos fatores de estiva e/ou peso específico de cada carga. A planilha calculará os valores de estabilidade e exibirá abaixo, basta rolar a planilha para baixo. OS VALORES UTILIZADOS FORAM RETIRADOS DA TABELA DE DADOS HIDROSTÁTICOS DE UM NAVIO PANAMAX E NEM TODOS OS VALORES SÃO EXATOS OU PRECISOS. Feita por Samuel Godinho.
B7: PORÕES | G7: PORÃO 7 | I7: PORÃO 6 | K7: PORÃO 5 | M7: PORÃO 4 | O7: PORÃO 3 | Q7: PORÃO 2 | S7: PORÃO 1
G8: 0 | I8: 0 | K8: 0 | M8: 0 | O8: 0 | Q8: 0 | S8: 0
B14: TANQUES | F14: 1000 | G14: 100 | K14: 1700 | O14: 0 | Q14: 1400 | U14: 1000 | Z14: BB
G16: 100 | K16: 1700 | O16: 20 | Q16: 1500 | Z16: CENTRAL
G18: 180 | K18: 1700 | O18: 30 | Q18: 1300 | Z18: BE
D22: FATOR DE ESTIVA | F22: - | G22: 1 | I22: 1 | K22: 1 | M22: 1 | O22: 1 | Q22: 1 | S22: 1 | U22: -
D23: PESO ESPECíFICO | F23: 1.025 | G23: 0.965 | K23: 1.025 | O23: 1 | Q23: 1.025 | U23: 1.025
G24: 0.965 | K24: 1.025 | O24: 1 | Q24: 1.025
G25: 0.965 | K25: 1.025 | O25: 1 | Q25: 1.025
D28: Porte Bruto (t) | F28: =IF(C77+F30>75622, "PBM EXCEDIDO",C77+F30) -> 23475 | U28: PBM = 75622t
D29: Deslocamento (t) | F29: =IFERROR(F28+'DADOS NAVIO'!C9, "VALORES EXCEDIDOS") -> 36755
D30: Porte Operacional (t) | F30: =SUM(C63:C74,'DADOS NAVIO'!C5,U14,F14) -> 11745
D31: Porte Comerciável (t) | F31: =IFERROR('DADOS NAVIO'!C19-F29, "VALORES EXCEDIDOS") -> 52147
D32: Volume Total (m3) | F32: =E77 -> 11468.173
D37: CÁLCULOS DE ESTABILIDADE DO NAVIO
D40: ESTABILIDADE TRANSVERSAL | O40: ESTABILIDADE LONGITUDINAL
D41: KG | F41: ='MOMENTOS DE EST.'!G25/'MOMENTOS DE EST.'!D25 -> 9.1223827 | O41: )o(G | Q41: ='MOMENTOS DE EST.'!M25/'MOMENTOS DE EST.'!K25 -> -3.8080528
D42: KM | F42: ='DADOS NAVIO'!C30 -> 11.689773 | O42: Hav | Q42: =Q44+'MOMENTOS DE EST.'!J31 -> 3.7297984
D43: GM | F43: =F42-F41 -> 2.5673901 | O43: Har | Q43: ='CÁLCULO ESTABILIDADE'!Q44:Y44+'MOMENTOS DE EST.'!J32 -> 4.4805377
D44: GGv | F44: ='MOMENTOS DE EST.'!E25 -> 0.61172198 | O44: Hm | Q44: ='MOMENTOS DE EST.'!L25 -> 4.0876445
D45: GM Corrigido | F45: =F43-F44 -> 1.9556682
D46: GG2 | F46: ='MOMENTOS DE EST.'!C28 -> 0.0039984006
B47: > 0 BE < 0 BB | D47: Ângulo de Banda | F47: ='MOMENTOS DE EST.'!C31 -> 0.072061429 | O47: Trim | Q47: =Q43-Q42 -> 0.75073937
C55: PESO | D55: FE ou PESO ESP | E55: VOLUME
B56: Porão 1 | C56: =S8 -> 0 | D56: =S22 -> 1 | E56: =C56*D56 -> 0
B57: Porão 2 | C57: =Q8 -> 0 | D57: =Q22 -> 1 | E57: =C57*D57 -> 0
B58: Porão 3 | C58: =O8 -> 0 | D58: =O22 -> 1 | E58: =C58*D58 -> 0
B59: Porão 4 | C59: =M8 -> 0 | D59: =M22 -> 1 | E59: =C59*D59 -> 0
B60: Porão 5 | C60: =K8 -> 0 | D60: =K22 -> 1 | E60: =C60*D60 -> 0
B61: Porão 6 | C61: =I8 -> 0 | D61: =I22 -> 1 | E61: =C61*D61 -> 0
B62: Porão 7 | C62: =G8 -> 0 | D62: =G22 -> 1 | E62: =C62*D62 -> 0
B63: TQ BB1 | C63: =Q14 -> 1400 | D63: =Q23 -> 1.025 | E63: =IFERROR(C63/D63, 0) -> 1365.8537
B64: TQ CE1 | C64: =Q16 -> 1500 | D64: =Q24 -> 1.025 | E64: =IFERROR(C64/D64, 0) -> 1463.4146
B65: TQ BE1 | C65: =Q18 -> 1300 | D65: =Q25 -> 1.025 | E65: =IFERROR(C65/D65, 0) -> 1268.2927
B66: TQ BB2 | C66: =O14 -> 0 | D66: =O23 -> 1 | E66: =IFERROR(C66/D66, 0) -> 0
B67: TQ CE2 | C67: =O16 -> 20 | D67: =O24 -> 1 | E67: =IFERROR(C67/D67, 0) -> 20
B68: TQ BE2 | C68: =O18 -> 30 | D68: =O25 -> 1 | E68: =IFERROR(C68/D68, 0) -> 30
B69: TQ BB3 | C69: =K14 -> 1700 | D69: =K23 -> 1.025 | E69: =IFERROR(C69/D69, 0) -> 1658.5366
...

Sheet MOMENTOS DE EST.
B2: Estabilidade Transversal | C2: Kg (m) | D2: Peso (t) | E2: GGv (m) | F2: Momento de Banda (t.m) | G2: Momento Transversal (t.m) | I2: Estabilidade Longitudinal | J2: LCG (m) | K2: Peso (t) | L2: Imersão (m) | M2: Momento Longitudinal (t.m)
B3: Navio Leve | C3: ='DADOS NAVIO'!C11 -> 11.2 | D3: ='DADOS NAVIO'!C9 -> 13280 | E3: - | F3: - | G3: =C3*D3 -> 148736 | I3: Navio Leve | J3: ='DADOS NAVIO'!C12 -> 14.72 | K3: ='DADOS NAVIO'!C9 -> 13280 | L3: ='DADOS NAVIO'!C8 -> 2.257 | M3: =J3*K3 -> 195481.6
B4: Porão 1 | C4: ='DADOS TQ&PORÃO'!D3 + ('CÁLCULO ESTABILIDADE'!E56/'DADOS TQ&PORÃO'!I3)/2 -> 2 | D4: ='CÁLCULO ESTABILIDADE'!C56 -> 0 | E4: - | F4: - | G4: =C4*D4 -> 0 | I4: Porão 1 | J4: ='DADOS TQ&PORÃO'!C3 -> -88.1 | K4: ='CÁLCULO ESTABILIDADE'!C56 -> 0 | L4: =(K4/'DADOS NAVIO'!$C$29)/100 -> 0 | M4: =J4*K4 -> 0
B5: Porão 2 | C5: ='DADOS TQ&PORÃO'!D4 + ('CÁLCULO ESTABILIDADE'!E57/'DADOS TQ&PORÃO'!I4)/2 -> 2 | D5: ='CÁLCULO ESTABILIDADE'!C57 -> 0 | E5: - | F5: - | G5: =C5*D5 -> 0 | I5: Porão 2 | J5: ='DADOS TQ&PORÃO'!C4 -> -62.5 | K5: ='CÁLCULO ESTABILIDADE'!C57 -> 0 | L5: =(K5/'DADOS NAVIO'!$C$29)/100 -> 0 | M5: =J5*K5 -> 0
B6: Porão 3 | C6: ='DADOS TQ&PORÃO'!D5 + ('CÁLCULO ESTABILIDADE'!E58/'DADOS TQ&PORÃO'!I5)/2 -> 2 | D6: ='CÁLCULO ESTABILIDADE'!C58 -> 0 | E6: - | F6: - | G6: =C6*D6 -> 0 | I6: Porão 3 | J6: ='DADOS TQ&PORÃO'!C5 -> -36.5 | K6: ='CÁLCULO ESTABILIDADE'!C58 -> 0 | L6: =(K6/'DADOS NAVIO'!$C$29)/100 -> 0 | M6: =J6*K6 -> 0
B7: Porão 4 | C7: ='DADOS TQ&PORÃO'!D6 + ('CÁLCULO ESTABILIDADE'!E59/'DADOS TQ&PORÃO'!I6)/2 -> 2 | D7: ='CÁLCULO ESTABILIDADE'!C59 -> 0 | E7: - | F7: - | G7: =C7*D7 -> 0 | I7: Porão 4 | J7: ='DADOS TQ&PORÃO'!C6 -> -10.1 | K7: ='CÁLCULO ESTABILIDADE'!C59 -> 0 | L7: =(K7/'DADOS NAVIO'!$C$29)/100 -> 0 | M7: =J7*K7 -> 0
B8: Porão 5 | C8: ='DADOS TQ&PORÃO'!D7 + ('CÁLCULO ESTABILIDADE'!E60/'DADOS TQ&PORÃO'!I7)/2 -> 2 | D8: ='CÁLCULO ESTABILIDADE'!C60 -> 0 | E8: - | F8: - | G8: =C8*D8 -> 0 | I8: Porão 5 | J8: ='DADOS TQ&PORÃO'!C7 -> 16.4 | K8: ='CÁLCULO ESTABILIDADE'!C60 -> 0 | L8: =(K8/'DADOS NAVIO'!$C$29)/100 -> 0 | M8: =J8*K8 -> 0
B9: Porão 6 | C9: ='DADOS TQ&PORÃO'!D8 + ('CÁLCULO ESTABILIDADE'!E61/'DADOS TQ&PORÃO'!I8)/2 -> 2 | D9: ='CÁLCULO ESTABILIDADE'!C61 -> 0 | E9: - | F9: - | G9: =C9*D9 -> 0 | I9: Porão 6 | J9: ='DADOS TQ&PORÃO'!C8 -> 42.8 | K9: ='CÁLCULO ESTABILIDADE'!C61 -> 0 | L9: =(K9/'DADOS NAVIO'!$C$29)/100 -> 0 | M9: =J9*K9 -> 0
B10: Porão 7 | C10: ='DADOS TQ&PORÃO'!D9 + ('CÁLCULO ESTABILIDADE'!E62/'DADOS TQ&PORÃO'!I9)/2 -> 2 | D10: ='CÁLCULO ESTABILIDADE'!C62 -> 0 | E10: - | F10: - | G10: =C10*D10 -> 0 | I10: Porão 7 | J10: ='DADOS TQ&PORÃO'!C9 -> 69.3 | K10: ='CÁLCULO ESTABILIDADE'!C62 -> 0 | L10: =(K10/'DADOS NAVIO'!$C$29)/100 -> 0 | M10: =J10*K10 -> 0
B11: TQ BB1 | C11: ='DADOS TQ&PORÃO'!D10 + ('CÁLCULO ESTABILIDADE'!E63/'DADOS TQ&PORÃO'!I10)/2 -> 6.8626723 | D11: ='CÁLCULO ESTABILIDADE'!C63 -> 1400 | E11: ='DADOS TQ&PORÃO'!F10*'CÁLCULO ESTABILIDADE'!D63/$D$25 -> 0.036657559 | F11: =D11*'DADOS TQ&PORÃO'!E10 -> -14000 | G11: =C11*D11 -> 9607.7413 | I11: TQ BB1 | J11: ='DADOS TQ&PORÃO'!C10 -> -75.3 | K11: ='CÁLCULO ESTABILIDADE'!C63 -> 1400 | L11: =(K11/'DADOS NAVIO'!$C$29)/100 -> 0.21849124 | M11: =J11*K11 -> -105420
B12: TQ CE1 | C12: ='DADOS TQ&PORÃO'!D11 + ('CÁLCULO ESTABILIDADE'!E64/'DADOS TQ&PORÃO'!I11)/2 -> 7.6736011 | D12: ='CÁLCULO ESTABILIDADE'!C64 -> 1500 | E12: ='DADOS TQ&PORÃO'!F11*'CÁLCULO ESTABILIDADE'!D64/$D$25 -> 0.034836066 | F12: =D12*'DADOS TQ&PORÃO'!E11 -> 0 | G12: =C12*D12 -> 11510.402 | I12: TQ CE1 | J12: ='DADOS TQ&PORÃO'!C11 -> -75.3 | K12: ='CÁLCULO ESTABILIDADE'!C64 -> 1500 | L12: =(K12/'DADOS NAVIO'!$C$29)/100 -> 0.23409776 | M12: =J12*K12 -> -112950
B13: TQ BE1 | C13: ='DADOS TQ&PORÃO'!D12 + ('CÁLCULO ESTABILIDADE'!E65/'DADOS TQ&PORÃO'!I12)/2 -> 6.4825127 | D13: ='CÁLCULO ESTABILIDADE'!C65 -> 1300 | E13: ='DADOS TQ&PORÃO'!F12*'CÁLCULO ESTABILIDADE'!D65/$D$25 -> 0.036202186 | F13: =D13*'DADOS TQ&PORÃO'!E12 -> 13000 | G13: =C13*D13 -> 8427.2665 | I13: TQ BE1 | J13: ='DADOS TQ&PORÃO'!C12 -> -75.3 | K13: ='CÁLCULO ESTABILIDADE'!C65 -> 1300 | L13: =(K13/'DADOS NAVIO'!$C$29)/100 -> 0.20288472 | M13: =J13*K13 -> -97890
B14: TQ BB2 | C14: ='DADOS TQ&PORÃO'!D13 + ('CÁLCULO ESTABILIDADE'!E66/'DADOS TQ&PORÃO'!I13)/2 -> 0.5 | D14: ='CÁLCULO ESTABILIDADE'!C66 -> 0 | E14: ='DADOS TQ&PORÃO'!F13*'CÁLCULO ESTABILIDADE'!D66/$D$25 -> 0.035097072 | F14: =D14*'DADOS TQ&PORÃO'!E13 -> 0 | G14: =C14*D14 -> 0 | I14: TQ BB2 | J14: ='DADOS TQ&PORÃO'!C13 -> -36.5 | K14: ='CÁLCULO ESTABILIDADE'!C66 -> 0 | L14: =(K14/'DADOS NAVIO'!$C$29)/100 -> 0 | M14: =J14*K14 -> 0
B15: TQ CE2 | C15: ='DADOS TQ&PORÃO'!D14 + ('CÁLCULO ESTABILIDADE'!E67/'DADOS TQ&PORÃO'!I14)/2 -> 0.59146341 | D15: ='CÁLCULO ESTABILIDADE'!C67 -> 20 | E15: ='DADOS TQ&PORÃO'!F14*'CÁLCULO ESTABILIDADE'!D67/$D$25 -> 0.036429872 | F15: =D15*'DADOS TQ&PORÃO'!E14 -> 0 | G15: =C15*D15 -> 11.829268 | I15: TQ CE2 | J15: ='DADOS TQ&PORÃO'!C14 -> -36.5 | K15: ='CÁLCULO ESTABILIDADE'!C67 -> 20 | L15: =(K15/'DADOS NAVIO'!$C$29)/100 -> 0.0031213034 | M15: =J15*K15 -> -730
B16: TQ BE2 | C16: ='DADOS TQ&PORÃO'!D15 + ('CÁLCULO ESTABILIDADE'!E68/'DADOS TQ&PORÃO'!I15)/2 -> 0.63888889 | D16: ='CÁLCULO ESTABILIDADE'!C68 -> 30 | E16: ='DADOS TQ&PORÃO'!F15*'CÁLCULO ESTABILIDADE'!D68/$D$25 -> 0.035985606 | F16: =D16*'DADOS TQ&PORÃO'!E15 -> 300 | G16: =C16*D16 -> 19.166667 | I16: TQ BE2 | J16: ='DADOS TQ&PORÃO'!C15 -> -36.5 | K16: ='CÁLCULO ESTABILIDADE'!C68 -> 30 | L16: =(K16/'DADOS NAVIO'!$C$29)/100 -> 0.0046819552 | M16: =J16*K16 -> -1095
B17: TQ BB3 | C17: ='DADOS TQ&PORÃO'!D16 + ('CÁLCULO ESTABILIDADE'!E69/'DADOS TQ&PORÃO'!I16)/2 -> 8.7926829 | D17: ='CÁLCULO ESTABILIDADE'!C69 -> 1700 | E17: ='DADOS TQ&PORÃO'!F16*'CÁLCULO ESTABILIDADE'!D69/$D$25 -> 0.034153005 | F17: =D17*'DADOS TQ&PORÃO'!E16 -> -17000 | G17: =C17*D17 -> 14947.561 | I17: TQ BB3 | J17: ='DADOS TQ&PORÃO'!C16 -> 3.15 | K17: ='CÁLCULO ESTABILIDADE'!C69 -> 1700 | L17: =(K17/'DADOS NAVIO'!$C$29)/100 -> 0.26531079 | M17: =J17*K17 -> 5355
B18: TQ CE3 | C18: ='DADOS TQ&PORÃO'!D17 + ('CÁLCULO ESTABILIDADE'!E70/'DADOS TQ&PORÃO'!I17)/2 -> 8.8483385 | D18: ='CÁLCULO ESTABILIDADE'!C70 -> 1700 | E18: ='DADOS TQ&PORÃO'!F17*'CÁLCULO ESTABILIDADE'!D70/$D$25 -> 0.033925319 | F18: =D18*'DADOS TQ&PORÃO'!E17 -> 0 | G18: =C18*D18 -> 15042.175 | I18: TQ CE3 | J18: ='DADOS TQ&PORÃO'!C17 -> 3.15 | K18: ='CÁLCULO ESTABILIDADE'!C70 -> 1700 | L18: =(K18/'DADOS NAVIO'!$C$29)/100 -> 0.26531079 | M18: =J18*K18 -> 5355
B19: TQ BE3 | C19: ='DADOS TQ&PORÃO'!D18 + ('CÁLCULO ESTABILIDADE'!E71/'DADOS TQ&PORÃO'!I18)/2 -> 8.7926829 | D19: ='CÁLCULO ESTABILIDADE'!C71 -> 1700 | E19: ='DADOS TQ&PORÃO'!F18*'CÁLCULO ESTABILIDADE'!D71/$D$25 -> 0.034153005 | F19: =D19*'DADOS TQ&PORÃO'!E18 -> 17000 | G19: =C19*D19 -> 14947.561 | I19: TQ BE3 | J19: ='DADOS TQ&PORÃO'!C18 -> 3.15 | K19: ='CÁLCULO ESTABILIDADE'!C71 -> 1700 | L19: =(K19/'DADOS NAVIO'!$C$29)/100 -> 0.26531079 | M19: =J19*K19 -> 5355
B20: TQ BB4 | C20: ='DADOS TQ&PORÃO'!D19 + ('CÁLCULO ESTABILIDADE'!E72/'DADOS TQ&PORÃO'!I19)/2 -> 0.99503317 | D20: ='CÁLCULO ESTABILIDADE'!C72 -> 100 | E20: ='DADOS TQ&PORÃO'!F19*'CÁLCULO ESTABILIDADE'!D72/$D$25 -> 0.033654316 | F20: =D20*'DADOS TQ&PORÃO'!E19 -> -1000 | G20: =C20*D20 -> 99.503317 | I20: TQ BB4 | J20: ='DADOS TQ&PORÃO'!C19 -> 56.05 | K20: ='CÁLCULO ESTABILIDADE'!C72 -> 100 | L20: =(K20/'DADOS NAVIO'!$C$29)/100 -> 0.015606517 | M20: =J20*K20 -> 5605
B21: TQ CE4 | C21: ='DADOS TQ&PORÃO'!D20 + ('CÁLCULO ESTABILIDADE'!E73/'DADOS TQ&PORÃO'!I20)/2 -> 1.0181347 | D21: ='CÁLCULO ESTABILIDADE'!C73 -> 100 | E21: ='DADOS TQ&PORÃO'!F20*'CÁLCULO ESTABILIDADE'!D73/$D$25 -> 0.032153805 | F21: =D21*'DADOS TQ&PORÃO'!E20 -> 0 | G21: =C21*D21 -> 101.81347 | I21: TQ CE4 | J21: ='DADOS TQ&PORÃO'!C20 -> 56.05 | K21: ='CÁLCULO ESTABILIDADE'!C73 -> 100 | L21: =(K21/'DADOS NAVIO'!$C$29)/100 -> 0.015606517 | M21: =J21*K21 -> 5605
B22: TQ BE4 | C22: ='DADOS TQ&PORÃO'!D21 + ('CÁLCULO ESTABILIDADE'!E74/'DADOS TQ&PORÃO'!I21)/2 -> 1.35826 | D22: ='CÁLCULO ESTABILIDADE'!C74 -> 180 | E22: ='DADOS TQ&PORÃO'!F21*'CÁLCULO ESTABILIDADE'!D74/$D$25 -> 0.034940468 | F22: =D22*'DADOS TQ&PORÃO'!E21 -> 1800 | G22: =C22*D22 -> 244.48679 | I22: TQ BE4 | J22: ='DADOS TQ&PORÃO'!C21 -> 56.05 | K22: ='CÁLCULO ESTABILIDADE'!C74 -> 180 | L22: =(K22/'DADOS NAVIO'!$C$29)/100 -> 0.028091731 | M22: =J22*K22 -> 10089
... B24: APTank | C24: ='DADOS TQ&PORÃO'!D23 + ('CÁLCULO ESTABILIDADE'!E76/'DADOS TQ&PORÃO'!I23)/2 -> 2.1260163 | D24: ='CÁLCULO ESTABILIDADE'!C76 -> 1000 | E24: ='DADOS TQ&PORÃO'!F23*'CÁLCULO ESTABILIDADE'!D76/$D$25 -> 0.10245902 | F24: =D24*'DADOS TQ&PORÃO'!E23 -> 0 | G24: =C24*D24 -> 2126.0163 | I24: APTank | J24: ='DADOS TQ&PORÃO'!C23 -> 95 | K24: ='CÁLCULO ESTABILIDADE'!C76 -> 1000 | L24: =(K24/'DADOS NAVIO'!$C$29)/100 -> 0.15606517 | M24: =J24*K24 -> 95000
B25: TOTAL | D25: =SUM(D3:D24) -> 25010 | E25: =SUM(E11:E24) -> 0.61172198 | F25: =SUM(F11:F24) -> 100 | G25: =SUM(G3:G24) -> 228150.79 | I25: TOTAL | K25: =SUM(K3:K24) -> 25010 | L25: =SUM(L3:L24) -> 4.0876445 | M25: =SUM(M3:M24) -> -95239.4
B26: DESLOCAMENTO (Verão) | C26: ='DADOS NAVIO'!C19 -> 88902 | I26: DESLOCAMENTO (Verão) | J26: ='DADOS NAVIO'!C19 -> 88902
B27: KG | C27: =G25/D25 -> 9.1223827 | I27: LCG | J27: =M25/K25 -> -3.8080528
B28: GG2 | C28: =F25/D25 -> 0.0039984006 | I28: LCB | J28: ='DADOS NAVIO'!C31 -> -6.5553132
B29: GM Corrigido | C29: =('DADOS NAVIO'!C30-'MOMENTOS DE EST.'!C27)+'MOMENTOS DE EST.'!E25 -> 3.1791121 | I29: BG | J29: =J28-'MOMENTOS DE EST.'!J27 -> -2.7472604
B30: tg(b) | C30: =C28/C29 -> 0.0012577099 | I30: Variação Total VT (m) | J30: =('MOMENTOS DE EST.'!K25*(J29)/'DADOS NAVIO'!C33)/100 -> -0.75073937
B31: Ângulo de Banda | C31: =DEGREES(ATAN(C30)) -> 0.072061429 | I31: Vav (m) | J31: ='DADOS NAVIO'!C35*'MOMENTOS DE EST.'!J30/'DADOS NAVIO'!C3 -> -0.35784612
I32: Var (m) | J32: =('DADOS NAVIO'!C36*'MOMENTOS DE EST.'!J30/'DADOS NAVIO'!C3)*-1 -> 0.39289326

Sheet DADOS TQ&PORÃO
B2: Tanque/Porão | C2: Distância Longitudinal do CG | D2: Altura p/ quilha | E2: Distância Lateral do CG | F2: Momento de inércia | G2: Volume total | H2: Altura | I2: Base x Comprimento
B3: Porão 1 | C3: -88.1 | D3: 2 | E3: 0 | F3: - | G3: 12969 | H3: 19.7 | I3: =G3/H3 -> 658.32487
B4: Porão 2 | C4: -62.5 | D4: 2 | E4: 0 | F4: - | G4: 12230 | H4: 19.2 | I4: =G4/H4 -> 636.97917
B5: Porão 3 | C5: -36.5 | D5: 2 | E5: 0 | F5: - | G5: 12541 | H5: 19.2 | I5: =G5/H5 -> 653.17708
B6: Porão 4 | C6: -10.1 | D6: 2 | E6: 0 | F6: - | G6: 12568 | H6: 19.2 | I6: =G6/H6 -> 654.58333
B7: Porão 5 | C7: 16.4 | D7: 2 | E7: 0 | F7: - | G7: 12606 | H7: 19.2 | I7: =G7/H7 -> 656.5625
B8: Porão 6 | C8: 42.8 | D8: 2 | E8: 0 | F8: - | G8: 12579 | H8: 19.2 | I8: =G8/H8 -> 655.15625
B9: Porão 7 | C9: 69.3 | D9: 2 | E9: 0 | F9: - | G9: 12565 | H9: 19.2 | I9: =G9/H9 -> 654.42708
B10: TQ BB1 | C10: -75.3 | D10: 0.5 | E10: -10 | F10: =I10*100/12 -> 894.44444 | G10: 161 | H10: 1.5 | I10: =G10/H10 -> 107.33333
B11: TQ CE1 | C11: -75.3 | D11: 0.5 | E11: 0 | F11: =I11*100/12 -> 850 | G11: 153 | H11: 1.5 | I11: =G11/H11 -> 102
B12: TQ BE1 | C12: -75.3 | D12: 0.5 | E12: 10 | F12: =I12*100/12 -> 883.33333 | G12: 159 | H12: 1.5 | I12: =G12/H12 -> 106
B13: TQ BB2 | C13: -36.5 | D13: 0.5 | E13: -10 | F13: =I13*100/12 -> 877.77778 | G13: 158 | H13: 1.5 | I13: =G13/H13 -> 105.33333
B14: TQ CE2 | C14: -36.5 | D14: 0.5 | E14: 0 | F14: =I14*100/12 -> 911.11111 | G14: 164 | H14: 1.5 | I14: =G14/H14 -> 109.33333
B15: TQ BE2 | C15: -36.5 | D15: 0.5 | E15: 10 | F15: =I15*100/12 -> 900 | G15: 162 | H15: 1.5 | I15: =G15/H15 -> 108
B16: TQ BB3 | C16: 3.15 | D16: 0.5 | E16: -10 | F16: =I16*100/12 -> 833.33333 | G16: 150 | H16: 1.5 | I16: =G16/H16 -> 100
B17: TQ CE3 | C17: 3.15 | D17: 0.5 | E17: 0 | F17: =I17*100/12 -> 827.77778 | G17: 149 | H17: 1.5 | I17: =G17/H17 -> 99.333333
B18: TQ BE3 | C18: 3.15 | D18: 0.5 | E18: 10 | F18: =I18*100/12 -> 833.33333 | G18: 150 | H18: 1.5 | I18: =G18/H18 -> 100
B19: TQ BB4 | C19: 56.05 | D19: 0.5 | E19: -10 | F19: =I19*100/12 -> 872.22222 | G19: 157 | H19: 1.5 | I19: =G19/H19 -> 104.66667
B20: TQ CE4 | C20: 56.05 | D20: 0.5 | E20: 0 | F20: =I20*100/12 -> 833.33333 | G20: 150 | H20: 1.5 | I20: =G20/H20 -> 100
B21: TQ BE4 | C21: 56.05 | D21: 0.5 | E21: 10 | F21: =I21*100/12 -> 905.55556 | G21: 163 | H21: 1.5 | I21: =G21/H21 -> 108.66667
... B23: APTank | C23: 95 | D23: 0.5 | E23: 0 | F23: =I23*100/12 -> 2500 | G23: 450 | H23: 1.5 | I23: =G23/H23 -> 300

Sheet DADOS NAVIO
B1: (valores aproximados da tabela de dados hidrostáticos)
B2: Nome | C2: MV GODINHO 2022
B3: LPP (m) | C3: 230
B4: LPP/2 (m) | C4: =C3/2 -> 115
B5: Constante Operacional (t) | C5: 15
B6: Boca (m) | C6: 32.2
B8: Calado Leve (m) | C8: 2.257
B9: Desloc Leve (t) | C9: 13280
B10: KM Leve (m) | C10: 12
B11: KG Leve (m) | C11: 11.2
B12: LCG Leve (m) | C12: 14.72
B13: TPC Leve (t/cm) | C13: 62.99
B14: MCC Leve (t.m/cm) | C14: 871.471
B15: Aranha-B Leve (m) | C15: -7.063
B16: Aranha-F Leve (m) | C16: -6.547
B18: Calado Verão (m) | C18: 13.6
... B24: Aranha-F Verão (m) | C24: 1.05
B25: Porte Bruto Verão | C25: =C19-C9 -> 75622
A27: INTERPOLAÇÃO | B27: Hmed (m) | C27: =C8+ (C28-C9)/(C19-C9)*(C18-C8) -> 4.0164535
B28: Deslocamento Atual (t) | C28: ='MOMENTOS DE EST.'!D25 -> 25010
B29: TPC (t/cm) | C29: =C13+ ($C$28-$C$9)/($C$19-$C$9)*(C21-C13) -> 64.075795
B30: KM (m) | C30: =C10+($C$28-$C$9)/($C$19-$C$9)*(C20-C10) -> 11.689773
B31: Aranha-B (m) | C31: =C15+ ($C$28-$C$9)/($C$19-$C$9)*(C23-C15) -> -6.5553132
B32: Aranha-F (m) | C32: =C16+ ($C$28-$C$9)/($C$19-$C$9)*(C24-C16) -> -5.368602
B33: MCC (t.m/cm) | C33: =C14+ ($C$28-$C$9)/($C$19-$C$9)*(C22-C14) -> 915.21753
B35: Lpp/2 + Aranha-F | C35: =C4+C32 -> 109.6314
B36: Lpp/2 - Aranha-F | C36: =C4-C32 -> 120.3686
B39: Feito por: Samuel Godinho.
